<mujoco model="panda nohand">
  <compiler angle="radian" meshdir="assets" autolimits="true"/>

  <default>
    <default class="panda">
      <material specular="0.5" shininess="0.25"/>
      <joint armature="0.1" damping="1" axis="0 0 1" range="-2.8973 2.8973" type="hinge"/>
      <general dyntype="none" biastype="affine" ctrlrange="-2.8973 2.8973" forcerange="-87 87"/>
      <default class="finger">
        <joint axis="0 1 0" type="slide" range="0 0.04"/>
      </default>

      <default class="panda/visual">
        <geom type="mesh" contype="0" conaffinity="0" group="2" margin="1.0" gap="1.0"/>
      </default>
      <default class="panda/collision">
        <geom type="mesh" group="3" margin="1.0" gap="1.0"/>
      </default>
      <site size="0.001" rgba="0.5 0.5 0.5 0.3" group="4"/>
    </default>

    <default class="whip">
      <default class="X">
        <joint type="hinge" axis="1 0 0" pos="0 0 0" springref="0" stiffness="0.242" damping="0.092" /> 
      </default>
      <default class="Y">
        <joint type="hinge" axis="0 1 0" pos="0 0 0" springref="0" stiffness="0.242" damping="0.092" /> 
      </default>
      <default class="Z">
        <geom type="capsule" material="white" fromto="0 0 0 0 0 0.03" size="0.006" mass="0.012" />
      </default>
    </default>  

    <default class="target">
      <geom rgba=".5 .5 .5 .4" group="3"/>
    </default>
  </default>

  <custom>
	  <!-- brax custom params -->
		<!-- <numeric data="1.3e-06 0.66 -0.00015 -0.073 0.058 2.4 2.9 -0.16  0.76 -0.12
                   0.41  -0.07  0.21  -0.037 0.11  -0.02  0.059  -0.01  0.032 -0.0056
                   0.017 -0.0031 0.0099 -0.0018 0.0059 -0.0011 0.0038 -0.00075 0.0026  -0.00057
                   0.002 -0.00049 0.0016  -0.00045 0.0015  -0.00043 0.0014 -0.00043 0.0013 -0.00043 
                   0.0012 -0.00043 0.0012 -0.00043 0.0011 -0.00041 0.00099 -0.00038 0.00088 -0.00034 
                   0.00075 -0.00029 0.0006 -0.00023 0.00045 -0.00016 0.0003 -9.2e-05 0.00017 -3.5e-05 
                   6.1e-05 0 0  -0.9 -5.997 0.022 1 0 0 0" 
              name="init_qpos"/> -->
  </custom>

  <asset>
    <texture builtin="gradient" height="100" rgb1=".4 .5 .6" rgb2="0 0 0" type="skybox" width="100"/>
    <texture builtin="flat" height="1278" mark="cross" markrgb="1 1 1" name="texgeom" random="0.01" rgb1="0.8 0.6 0.4" rgb2="0.8 0.6 0.4" type="cube" width="127"/>
    <texture builtin="checker" height="100" name="texplane" rgb1="0 0 0" rgb2="0.8 0.8 0.8" type="2d" width="100"/>
    <material name="MatPlane" reflectance="0.5" shininess="1" specular="1" texrepeat="60 60" texture="texplane"/>
    <material name="geom" texture="texgeom" texuniform="true"/>

    <material class="panda" name="white" rgba="1 1 1 1"/>
    <material class="panda" name="off_white" rgba="0.901961 0.921569 0.929412 1"/>
    <material class="panda" name="dark_grey" rgba="0.25 0.25 0.25 1"/>
    <material class="panda" name="green" rgba="0 1 0 1"/>
    <material class="panda" name="light_blue" rgba="0.039216 0.541176 0.780392 1"/>

    <!-- Collision meshes -->
    <mesh name="link0_c" file="link0.stl"/>
    <mesh name="link1_c" file="link1.stl"/>
    <mesh name="link2_c" file="link2.stl"/>
    <mesh name="link3_c" file="link3.stl"/>
    <mesh name="link4_c" file="link4.stl"/>
    <mesh name="link5_c0" file="link5_collision_0.obj"/>
    <mesh name="link5_c1" file="link5_collision_1.obj"/>
    <mesh name="link5_c2" file="link5_collision_2.obj"/>
    <mesh name="link6_c" file="link6.stl"/>
    <mesh name="link7_c" file="link7.stl"/>
    
  </asset>

  <worldbody>
    <light cutoff="100" diffuse="1 1 1" dir="-0 0 -1.3" directional="true" exponent="1" pos="0 0 1.3" specular=".1 .1 .1"/>
    <geom material="MatPlane" name="floor" pos="0 0 0" size="20 20 0.125" type="plane"/>
    <body name="link0" childclass="panda">
      <joint name="dummy0" axis="0 1 0" type="hinge" range="-1e-6 1e-6" pos="0 0 0"/>
      <joint name="dummy1" axis="1 0 0" type="hinge" range="-1e-6 1e-6" pos="0 0 0"/>
      <inertial mass="0.629769" pos="-0.041018 -0.00014 0.049974"
        fullinertia="0.00315 0.00388 0.004285 8.2904e-7 0.00015 8.2299e-6"/>
      <geom mesh="link0_c" class="panda/collision"/>
      <body name="link1" pos="0 0 0.333">
        <inertial mass="4.970684" pos="0.003875 0.002081 -0.04762"
          fullinertia="0.70337 0.70661 0.0091170 -0.00013900 0.0067720 0.019169"/>
        <joint name="joint1"/>
        <geom mesh="link1_c" class="panda/collision"/>
        <body name="link2" quat="1 -1 0 0">
          <inertial mass="0.646926" pos="-0.003141 -0.02872 0.003495"
            fullinertia="0.0079620 2.8110e-2 2.5995e-2 -3.925e-3 1.0254e-2 7.04e-4"/>
          <joint name="joint2" range="-1.7628 1.7628"/>
          <geom mesh="link2_c" class="panda/collision"/>
          <body name="link3" pos="0 -0.316 0" quat="1 1 0 0">
            <joint name="joint3"/>
            <inertial mass="3.228604" pos="2.7518e-2 3.9252e-2 -6.6502e-2"
              fullinertia="3.7242e-2 3.6155e-2 1.083e-2 -4.761e-3 -1.1396e-2 -1.2805e-2"/>
            <geom mesh="link3_c" class="panda/collision"/>
            <body name="link4" pos="0.0825 0 0" quat="1 1 0 0">
              <inertial mass="3.587895" pos="-5.317e-2 1.04419e-1 2.7454e-2"
                fullinertia="2.5853e-2 1.9552e-2 2.8323e-2 7.796e-3 -1.332e-3 8.641e-3"/>
              <joint name="joint4" range="-3.0718 -0.0698"/>
              <geom mesh="link4_c" class="panda/collision"/>
              <body name="link5" pos="-0.0825 0.384 0" quat="1 -1 0 0">
                <inertial mass="1.225946" pos="-1.1953e-2 4.1065e-2 -3.8437e-2"
                  fullinertia="3.5549e-2 2.9474e-2 8.627e-3 -2.117e-3 -4.037e-3 2.29e-4"/>
                <joint name="joint5"/>
                <geom mesh="link5_c0" class="panda/collision"/>
                <geom mesh="link5_c1" class="panda/collision"/>
                <geom mesh="link5_c2" class="panda/collision"/>
                <body name="link6" quat="1 1 0 0">
                  <inertial mass="1.666555" pos="6.0149e-2 -1.4117e-2 -1.0517e-2"
                    fullinertia="1.964e-3 4.354e-3 5.433e-3 1.09e-4 -1.158e-3 3.41e-4"/>
                  <joint name="joint6" range="-0.0175 3.7525"/>
                  <geom mesh="link6_c" class="panda/collision"/>
                  <body name="link7" pos="0.088 0 0" quat="1 1 0 0">
                    <inertial mass="7.35522e-01" pos="1.0517e-2 -4.252e-3 6.1597e-2"
                      fullinertia="1.2516e-2 1.0027e-2 4.815e-3 -4.28e-4 -1.196e-3 -7.41e-4"/>
                    <joint name="joint7"/>
                    <geom mesh="link7_c" class="panda/collision"/>
                    <!-- whip begin-->
                    <geom type="sphere" pos="0 0 0.107" size="0.045" material="white" contype="0" conaffinity="0"/>
                      <body name="B0" pos="0 0 0.152" childclass="whip">
                        <joint class="X"/>
                        <joint class="Y"/>
                        <geom class="Z"/>
                      <body name="B1" pos="0 0 0.036">
                        <joint class="X"/>
                        <joint class="Y"/>
                        <geom class="Z"/>
                      <body name="B2" pos="0 0 0.036">
                        <joint class="X"/>
                        <joint class="Y"/>
                        <geom class="Z"/>
                      <body name="B3" pos="0 0 0.036">
                        <joint class="X"/>
                        <joint class="Y"/>
                        <geom class="Z"/>
                      <body name="B4" pos="0 0 0.036">
                        <joint class="X"/>
                        <joint class="Y"/>
                        <geom class="Z"/>
                      <body name="B5" pos="0 0 0.036">
                        <joint class="X"/>
                        <joint class="Y"/>
                        <geom class="Z"/>
                      <body name="B6" pos="0 0 0.036">
                        <joint class="X"/>
                        <joint class="Y"/>
                        <geom class="Z"/>
                      <body name="B7" pos="0 0 0.036">
                        <joint class="X"/>
                        <joint class="Y"/>
                        <geom class="Z"/>
                      <body name="B8" pos="0 0 0.036">
                        <joint class="X"/>
                        <joint class="Y"/>
                        <geom class="Z"/>
                      <body name="B9" pos="0 0 0.036">
                        <joint class="X"/>
                        <joint class="Y"/>
                        <geom class="Z"/>
                      <body name="B10" pos="0 0 0.036">
                        <joint class="X"/>
                        <joint class="Y"/>
                        <geom class="Z"/>
                      <body name="B11" pos="0 0 0.036">
                        <joint class="X"/>
                        <joint class="Y"/>
                        <geom class="Z"/>
                      <body name="B12" pos="0 0 0.036">
                        <joint class="X"/>
                        <joint class="Y"/>
                        <geom class="Z"/>
                      <body name="B13" pos="0 0 0.036">
                        <joint class="X"/>
                        <joint class="Y"/>
                        <geom class="Z"/>
                      <body name="B14" pos="0 0 0.036">
                        <joint class="X"/>
                        <joint class="Y"/>
                        <geom class="Z"/>
                      <!-- <body name="B15" pos="0 0 0.036">
                        <joint class="X"/>
                        <joint class="Y"/>
                        <geom class="Z"/>
                      <body name="B16" pos="0 0 0.036">
                        <joint class="X"/>
                        <joint class="Y"/>
                        <geom class="Z"/>
                      <body name="B17" pos="0 0 0.036">
                        <joint class="X"/>
                        <joint class="Y"/>
                        <geom class="Z"/>
                      <body name="B18" pos="0 0 0.036">
                        <joint class="X"/>
                        <joint class="Y"/>
                        <geom class="Z"/>
                      <body name="B19" pos="0 0 0.036">
                        <joint class="X"/>
                        <joint class="Y"/>
                        <geom class="Z"/>
                      <body name="B20" pos="0 0 0.036">
                        <joint class="X"/>
                        <joint class="Y"/>
                        <geom class="Z"/>
                      <body name="B21" pos="0 0 0.036">
                        <joint class="X"/>
                        <joint class="Y"/>
                        <geom class="Z"/>
                      <body name="B22" pos="0 0 0.036">
                        <joint class="X"/>
                        <joint class="Y"/>
                        <geom class="Z"/>
                      <body name="B23" pos="0 0 0.036">
                        <joint class="X"/>
                        <joint class="Y"/>
                        <geom class="Z"/>
                      <body name="B24" pos="0 0 0.036">
                        <joint class="X"/>
                        <joint class="Y"/>
                        <geom class="Z"/>                                -->
                    <!-- </body>                              
                    </body>                              
                    </body>                              
                    </body>                              
                    </body>                              
                    </body>                              
                    </body>                              
                    </body>                              
                    </body>                              
                    </body>                               -->
                    </body>                              
                    </body>                              
                    </body>                              
                    </body>                              
                    </body>                              
                    </body>                              
                    </body>                              
                    </body>                              
                    </body>                                
                    </body>  
                    </body>                             
                    </body>                            
                    </body>                        
                    </body>                      
                    </body>  
                      <!-- whip end -->
                  </body>
                </body>
              </body>
            </body>
          </body>
        </body>
      </body>
    </body>

    <body name="target" pos="-0.9 0 1.0">
      <geom type="sphere" size=".05 .05 .05" class="target" name="target"/>
      <freejoint name="target"/>
      <!-- <site type="sphere" size=".05 .05 .05" name="target_site"/> -->
    </body>
  </worldbody>

  <actuator>
    <general class="panda" name="actuator1" joint="joint1" gainprm="4500" biasprm="0 -4500 -450"/>
    <general class="panda" name="actuator2" joint="joint2" gainprm="4500" biasprm="0 -4500 -450"
      ctrlrange="-1.7628 1.7628"/>
    <general class="panda" name="actuator3" joint="joint3" gainprm="3500" biasprm="0 -3500 -350"/>
    <general class="panda" name="actuator4" joint="joint4" gainprm="3500" biasprm="0 -3500 -350"
      ctrlrange="-3.0718 -0.0698"/>
    <general class="panda" name="actuator5" joint="joint5" gainprm="2000" biasprm="0 -2000 -200" forcerange="-12 12"/>
    <general class="panda" name="actuator6" joint="joint6" gainprm="2000" biasprm="0 -2000 -200" forcerange="-12 12"
      ctrlrange="-0.0175 3.7525"/>
    <general class="panda" name="actuator7" joint="joint7" gainprm="2000" biasprm="0 -2000 -200" forcerange="-12 12"/>
  </actuator>

</mujoco>