<mujoco model="whipping_brax">
  <compiler angle="radian" autolimits="true"/>
  <option integrator="Euler" impratio="10" timestep="0.001"/> 
  <!-- 目前brax只支持Euler积分器 mj.opt.integrator=0-->
  <!-- multiccd="enable" 用于轻量化box的碰撞检测 brax不支持 -->
  <statistic extent="1.5" center="-0.9 0 1"/>
  <visual>
    <headlight diffuse="0.6 0.6 0.6"  ambient="0.3 0.3 0.3" specular="0 0 0"/>
    <rgba haze="0.15 0.25 0.35 1"/>
    <global azimuth="120" elevation="-20" offwidth="1000" offheight="1000"/>
  </visual>

  <!-- brax custom params -->
  <!-- <custom>
		<numeric data="1.3e-06 0.66 -0.00015 -0.073 0.058 2.4 2.9 -0.16  0.76 -0.12
                   0.41  -0.07  0.21  -0.037 0.11  -0.02  0.059  -0.01  0.032 -0.0056
                   0.017 -0.0031 0.0099 -0.0018 0.0059 -0.0011 0.0038 -0.00075 0.0026  -0.00057
                   0.002 -0.00049 0.0016  -0.00045 0.0015  -0.00043 0.0014 -0.00043 0.0013 -0.00043 
                   0.0012 -0.00043 0.0012 -0.00043 0.0011 -0.00041 0.00099 -0.00038 0.00088 -0.00034 
                   0.00075 -0.00029 0.0006 -0.00023 0.00045 -0.00016 0.0003 -9.2e-05 0.00017 -3.5e-05 
                   6.1e-05 0 0  -0.9 -5.997 0.022 1 0 0 0" 
              name="init_qpos"/>
  </custom> -->

  <default>
    <default class="target">
      <geom rgba=".5 .5 .5 .4" group="3"/>
    </default>

    <default class="base">
      <geom type="mesh" contype="0" conaffinity="0" group="2"/> <!-- 不检查mesh物体的碰撞 -->
    </default>

    <default class="panda">
      <material specular="0.5" shininess="0.25"/>
      <joint armature="0.1" damping="1" axis="0 0 1" range="-2.8973 2.8973"/>
      <general dyntype="none" biastype="affine" ctrlrange="-2.8973 2.8973" forcerange="-87 87"/>
      <default class="finger">
        <joint axis="0 1 0" type="slide" range="0 0.04"/>
      </default>
      <default class="dummy">
        <joint axis="0 1 0" type="slide" range="0 1e8"/>
      </default>
      <default class="collision">
        <geom type="mesh" group="3"/>
      </default>
      <site size="0.001" rgba="0.5 0.5 0.5 0.3" group="4"/>
    </default>

    <default class="whip">
      <default class="X">
        <joint type="hinge" axis="1 0 0" pos="0 0 0" springref="0" stiffness="0.242" damping="0.092" /> 
      </default>
      <default class="Y">
        <joint type="hinge" axis="0 1 0" pos="0 0 0" springref="0" stiffness="0.242" damping="0.092" /> 
      </default>
      <default class="Z0">
        <geom type="sphere" material="white" pos="0 0 0.036" size="0.006" mass="0.012" />
      </default>
      <default class="Z1">
        <geom type="box" material="off_white" fromto="0 0 0 0 0 0.036" size="0.006" mass="0" />
        <!-- Brax不支持cylinder的碰撞检测, 令对应的mj.geom_contype[i]和mj.geom_conaffinity[i]=0 -->
      </default>
    </default>    
  </default>

  <asset>
    <texture type="skybox" builtin="gradient" rgb1="0.3 0.5 0.7" rgb2="0 0 0" width="512" height="3072"/>
    <texture type="2d" name="groundplane" builtin="checker" mark="edge" rgb1="0.2 0.3 0.4" rgb2="0.1 0.2 0.3" markrgb="0.8 0.8 0.8" width="300" height="300"/>
    <material name="groundplane" texture="groundplane" texuniform="true" texrepeat="5 5" reflectance="0.2"/>

    <material class="panda" name="white" rgba="1 1 1 1"/>
    <material class="panda" name="off_white" rgba="0.901961 0.921569 0.929412 1"/>
    <material class="panda" name="dark_grey" rgba="0.25 0.25 0.25 1"/>
    <material class="panda" name="green" rgba="0 1 0 1"/>
    <material class="panda" name="light_blue" rgba="0.039216 0.541176 0.780392 1"/>

    <mesh name="link0_c" file="assets/link0.stl"/>
    <mesh name="link1_c" file="assets/link1.stl"/>
    <mesh name="link2_c" file="assets/link2.stl"/>
    <mesh name="link3_c" file="assets/link3.stl"/>
    <mesh name="link4_c" file="assets/link4.stl"/>
    <mesh name="link5_c0" file="assets/link5_collision_0.obj"/>
    <mesh name="link5_c1" file="assets/link5_collision_1.obj"/>
    <mesh name="link5_c2" file="assets/link5_collision_2.obj"/>
    <mesh name="link6_c" file="assets/link6.stl"/>
    <mesh name="link7_c" file="assets/link7.stl"/>
  </asset>

  <worldbody>
    <geom name="floor" size="0 0 0.05" type="plane" material="groundplane"/>
    <geom mesh="link0_c" conaffinity="0" contype="0"/>
    <body name="link1" pos="0 0 0.333" childclass="panda">
      <inertial mass="4.970684" pos="0.003875 0.002081 -0.04762"
          fullinertia="0.70337 0.70661 0.0091170 -0.00013900 0.0067720 0.019169"/>
      <joint name="joint1"/>
      <geom mesh="link1_c"/>
      <body name="link2" quat="1 -1 0 0">
        <inertial mass="0.646926" pos="-0.003141 -0.02872 0.003495"
            fullinertia="0.0079620 2.8110e-2 2.5995e-2 -3.925e-3 1.0254e-2 7.04e-4"/>
        <joint name="joint2" range="-1.7628 1.7628"/>
        <geom mesh="link2_c"/>
        <body name="link3" pos="0 -0.316 0" quat="1 1 0 0">
          <joint name="joint3"/>
          <inertial mass="3.228604" pos="2.7518e-2 3.9252e-2 -6.6502e-2"
              fullinertia="3.7242e-2 3.6155e-2 1.083e-2 -4.761e-3 -1.1396e-2 -1.2805e-2"/>
          <geom mesh="link3_c"/>
          <body name="link4" pos="0.0825 0 0" quat="1 1 0 0">
            <inertial mass="3.587895" pos="-5.317e-2 1.04419e-1 2.7454e-2"
                fullinertia="2.5853e-2 1.9552e-2 2.8323e-2 7.796e-3 -1.332e-3 8.641e-3"/>
            <joint name="joint4" range="-3.0718 -0.0698"/>
            <geom mesh="link4_c"/>
            <body name="link5" pos="-0.0825 0.384 0" quat="1 -1 0 0">
              <inertial mass="1.225946" pos="-1.1953e-2 4.1065e-2 -3.8437e-2"
                  fullinertia="3.5549e-2 2.9474e-2 8.627e-3 -2.117e-3 -4.037e-3 2.29e-4"/>
              <joint name="joint5"/>
              <geom mesh="link5_c0"/>
              <geom mesh="link5_c1"/>
              <geom mesh="link5_c2"/>
              <body name="link6" quat="1 1 0 0">
                <inertial mass="1.666555" pos="6.0149e-2 -1.4117e-2 -1.0517e-2"
                    fullinertia="1.964e-3 4.354e-3 5.433e-3 1.09e-4 -1.158e-3 3.41e-4"/>
                <joint name="joint6" range="-0.0175 3.7525"/>
                <geom mesh="link6_c"/>
                <body name="link7" pos="0.088 0 0" quat="1 1 0 0">
                  <inertial mass="7.35522e-01" pos="1.0517e-2 -4.252e-3 6.1597e-2"
                      fullinertia="1.2516e-2 1.0027e-2 4.815e-3 -4.28e-4 -1.196e-3 -7.41e-4"/>
                  <joint name="joint7"/>
                  <geom mesh="link7_c"/>
                  <geom type="sphere" pos="0 0 0.107" size="0.045" material="white"/>
                    <body name="B0" pos="0 0 0.152">
                      <joint class="X"/>
                      <joint class="Y"/>
                      <geom class="Z0"/>
                      <geom class="Z1"/>
                    <body name="B1" pos="0 0 0.036">
                      <joint class="X"/>
                      <joint class="Y"/>
                      <geom class="Z0"/>
                      <geom class="Z1"/>
                    <body name="B2" pos="0 0 0.036">
                      <joint class="X"/>
                      <joint class="Y"/>
                      <geom class="Z0"/>
                      <geom class="Z1"/>
                    <body name="B3" pos="0 0 0.036">
                      <joint class="X"/>
                      <joint class="Y"/>
                      <geom class="Z0"/>
                      <geom class="Z1"/>
                    <body name="B4" pos="0 0 0.036">
                      <joint class="X"/>
                      <joint class="Y"/>
                      <geom class="Z0"/>
                      <geom class="Z1"/>
                    <body name="B5" pos="0 0 0.036">
                      <joint class="X"/>
                      <joint class="Y"/>
                      <geom class="Z0"/>
                      <geom class="Z1"/>
                    <body name="B6" pos="0 0 0.036">
                      <joint class="X"/>
                      <joint class="Y"/>
                      <geom class="Z0"/>
                      <geom class="Z1"/>
                    <body name="B7" pos="0 0 0.036">
                      <joint class="X"/>
                      <joint class="Y"/>
                      <geom class="Z0"/>
                      <geom class="Z1"/>
                    <body name="B8" pos="0 0 0.036">
                      <joint class="X"/>
                      <joint class="Y"/>
                      <geom class="Z0"/>
                      <geom class="Z1"/>
                    <body name="B9" pos="0 0 0.036">
                      <joint class="X"/>
                      <joint class="Y"/>
                      <geom class="Z0"/>
                      <geom class="Z1"/>
                    <body name="B10" pos="0 0 0.036">
                      <joint class="X"/>
                      <joint class="Y"/>
                      <geom class="Z0"/>
                      <geom class="Z1"/>
                    <body name="B11" pos="0 0 0.036">
                      <joint class="X"/>
                      <joint class="Y"/>
                      <geom class="Z0"/>
                      <geom class="Z1"/>
                    <body name="B12" pos="0 0 0.036">
                      <joint class="X"/>
                      <joint class="Y"/>
                      <geom class="Z0"/>
                      <geom class="Z1"/>
                    <body name="B13" pos="0 0 0.036">
                      <joint class="X"/>
                      <joint class="Y"/>
                      <geom class="Z0"/>
                      <geom class="Z1"/>
                    <body name="B14" pos="0 0 0.036">
                      <joint class="X"/>
                      <joint class="Y"/>
                      <geom class="Z0"/>
                      <geom class="Z1"/>
                    <body name="B15" pos="0 0 0.036">
                      <joint class="X"/>
                      <joint class="Y"/>
                      <geom class="Z0"/>
                      <geom class="Z1"/>
                    <body name="B16" pos="0 0 0.036">
                      <joint class="X"/>
                      <joint class="Y"/>
                      <geom class="Z0"/>
                      <geom class="Z1"/>
                    <body name="B17" pos="0 0 0.036">
                      <joint class="X"/>
                      <joint class="Y"/>
                      <geom class="Z0"/>
                      <geom class="Z1"/>
                    <body name="B18" pos="0 0 0.036">
                      <joint class="X"/>
                      <joint class="Y"/>
                      <geom class="Z0"/>
                      <geom class="Z1"/>
                    <body name="B19" pos="0 0 0.036">
                      <joint class="X"/>
                      <joint class="Y"/>
                      <geom class="Z0"/>
                      <geom class="Z1"/>
                    <body name="B20" pos="0 0 0.036">
                      <joint class="X"/>
                      <joint class="Y"/>
                      <geom class="Z0"/>
                      <geom class="Z1"/>
                    <body name="B21" pos="0 0 0.036">
                      <joint class="X"/>
                      <joint class="Y"/>
                      <geom class="Z0"/>
                      <geom class="Z1"/>
                    <body name="B22" pos="0 0 0.036">
                      <joint class="X"/>
                      <joint class="Y"/>
                      <geom class="Z0"/>
                      <geom class="Z1"/>
                    <body name="B23" pos="0 0 0.036">
                      <joint class="X"/>
                      <joint class="Y"/>
                      <geom class="Z0"/>
                      <geom class="Z1"/>
                    <body name="B24" pos="0 0 0.036">
                      <joint class="X"/>
                      <joint class="Y"/>
                      <geom class="Z0"/>
                      <geom class="Z1"/>                             
                    </body>                              
                    </body>                              
                    </body>                              
                    </body>                              
                    </body>                              
                    </body>                              
                    </body>                              
                    </body>                              
                    </body>                              
                    </body>                              
                    </body>                              
                    </body>                              
                    </body>                              
                    </body>                              
                    </body>                              
                    </body>                              
                    </body>                              
                    </body>                              
                    </body>                                
                    </body>  
                    </body>                             
                    </body>                            
                    </body>                        
                    </body>                      
                    </body>  
                </body> <!-- link收尾 -->
              </body>
            </body>
          </body>
        </body>
      </body>
    </body>

    <body name="target" pos="-0.9 0 1.0">
      <geom type="sphere" size=".05 .05 .05" class="target" name="target"/>
      <freejoint name="target"/>
      <site type="sphere" size=".05 .05 .05" name="target_site"/>
    </body>
  </worldbody>

  <sensor>
    <touch name="hit" site="target_site"/>
  </sensor>

  <actuator>
    <!-- 作用在joint上的forcerange指的是力矩 -->
    <general class="panda" name="actuator1" joint="joint1" gainprm="4500" biasprm="0 -4500 -450"/>
    <general class="panda" name="actuator2" joint="joint2" gainprm="4500" biasprm="0 -4500 -450" ctrlrange="-1.7628 1.7628"/>
    <general class="panda" name="actuator3" joint="joint3" gainprm="3500" biasprm="0 -3500 -350"/>
    <general class="panda" name="actuator4" joint="joint4" gainprm="3500" biasprm="0 -3500 -350" ctrlrange="-3.0718 -0.0698"/>
    <general class="panda" name="actuator5" joint="joint5" gainprm="2000" biasprm="0 -2000 -200" forcerange="-12 12"/>
    <general class="panda" name="actuator6" joint="joint6" gainprm="2000" biasprm="0 -2000 -200" forcerange="-12 12" ctrlrange="-0.0175 3.7525"/>
    <general class="panda" name="actuator7" joint="joint7" gainprm="2000" biasprm="0 -2000 -200" forcerange="-12 12"/>
  </actuator>

</mujoco>
